Traceback (most recent call last):
  File "/Users/hannaziegler/opt/anaconda3/envs/jbook/lib/python3.7/site-packages/jupyter_cache/executors/utils.py", line 56, in single_nb_execution
    record_timing=False,
  File "/Users/hannaziegler/opt/anaconda3/envs/jbook/lib/python3.7/site-packages/nbclient/client.py", line 1117, in execute
    return NotebookClient(nb=nb, resources=resources, km=km, **kwargs).execute()
  File "/Users/hannaziegler/opt/anaconda3/envs/jbook/lib/python3.7/site-packages/nbclient/util.py", line 78, in wrapped
    return just_run(coro(*args, **kwargs))
  File "/Users/hannaziegler/opt/anaconda3/envs/jbook/lib/python3.7/site-packages/nbclient/util.py", line 57, in just_run
    return loop.run_until_complete(coro)
  File "/Users/hannaziegler/opt/anaconda3/envs/jbook/lib/python3.7/asyncio/base_events.py", line 587, in run_until_complete
    return future.result()
  File "/Users/hannaziegler/opt/anaconda3/envs/jbook/lib/python3.7/site-packages/nbclient/client.py", line 559, in async_execute
    cell, index, execution_count=self.code_cells_executed + 1
  File "/Users/hannaziegler/opt/anaconda3/envs/jbook/lib/python3.7/site-packages/nbclient/client.py", line 862, in async_execute_cell
    self._check_raise_for_error(cell, exec_reply)
  File "/Users/hannaziegler/opt/anaconda3/envs/jbook/lib/python3.7/site-packages/nbclient/client.py", line 765, in _check_raise_for_error
    raise CellExecutionError.from_cell_and_msg(cell, exec_reply_content)
nbclient.exceptions.CellExecutionError: An error occurred while executing the following cell:
------------------
# Sort dataframe by date
df = df.sort_values(by="date")

# Convert date to pd datetime object
df['date'] = pd.to_datetime(df.date,format='%Y-%m-%d')

# Extracting day month year from date
df['month'] = df['date'].dt.month
df['year'] = df['date'].dt.year
df['month_year'] = df['date'].dt.to_period('M')
------------------

[0;31m---------------------------------------------------------------------------[0m
[0;31mNameError[0m                                 Traceback (most recent call last)
[0;32m/var/folders/g7/m5kf9xs14511y51_chx__fs80000gn/T/ipykernel_92913/2927673444.py[0m in [0;36m<module>[0;34m[0m
[1;32m      1[0m [0;31m# Sort dataframe by date[0m[0;34m[0m[0;34m[0m[0;34m[0m[0m
[0;32m----> 2[0;31m [0mdf[0m [0;34m=[0m [0mdf[0m[0;34m.[0m[0msort_values[0m[0;34m([0m[0mby[0m[0;34m=[0m[0;34m"date"[0m[0;34m)[0m[0;34m[0m[0;34m[0m[0m
[0m[1;32m      3[0m [0;34m[0m[0m
[1;32m      4[0m [0;31m# Convert date to pd datetime object[0m[0;34m[0m[0;34m[0m[0;34m[0m[0m
[1;32m      5[0m [0mdf[0m[0;34m[[0m[0;34m'date'[0m[0;34m][0m [0;34m=[0m [0mpd[0m[0;34m.[0m[0mto_datetime[0m[0;34m([0m[0mdf[0m[0;34m.[0m[0mdate[0m[0;34m,[0m[0mformat[0m[0;34m=[0m[0;34m'%Y-%m-%d'[0m[0;34m)[0m[0;34m[0m[0;34m[0m[0m

[0;31mNameError[0m: name 'df' is not defined
NameError: name 'df' is not defined

